<?xml version="1.0" encoding="UTF-8"?>
<testng-results ignored="0" total="1" passed="0" failed="1" skipped="0">
  <reporter-output>
  </reporter-output>
  <suite started-at="2023-03-03T15:19:01 EET" name="Default suite" finished-at="2023-03-03T15:19:08 EET" duration-ms="7524">
    <groups>
    </groups>
    <test started-at="2023-03-03T15:19:01 EET" name="Default test" finished-at="2023-03-03T15:19:08 EET" duration-ms="7524">
      <class name="xyzfinal.Myclass">
        <test-method is-config="true" signature="mysetup()[pri:0, instance:xyzfinal.Myclass@110844f6]" started-at="2023-03-03T15:19:01 EET" name="mysetup" finished-at="2023-03-03T15:19:02 EET" duration-ms="1444" status="PASS">
          <reporter-output>
          </reporter-output>
        </test-method> <!-- mysetup -->
        <test-method signature="check_the_number_searches()[pri:0, instance:xyzfinal.Myclass@110844f6]" started-at="2023-03-03T15:19:02 EET" name="check_the_number_searches" finished-at="2023-03-03T15:19:08 EET" duration-ms="6019" status="FAIL">
          <exception class="java.lang.AssertionError">
            <message>
              <![CDATA[The following asserts failed:
wlh 3m n3ml test expected [10] but found [25600]]]>
            </message>
            <full-stacktrace>
              <![CDATA[java.lang.AssertionError: The following asserts failed:
wlh 3m n3ml test expected [10] but found [25600]
at org.testng.asserts.SoftAssert.assertAll(SoftAssert.java:47)
at org.testng.asserts.SoftAssert.assertAll(SoftAssert.java:31)
at xyzfinal.Myclass.check_the_number_searches(Myclass.java:52)
at java.base/jdk.internal.reflect.DirectMethodHandleAccessor.invoke(DirectMethodHandleAccessor.java:104)
at java.base/java.lang.reflect.Method.invoke(Method.java:578)
at org.testng.internal.MethodInvocationHelper.invokeMethod(MethodInvocationHelper.java:133)
at org.testng.internal.TestInvoker.invokeMethod(TestInvoker.java:598)
at org.testng.internal.TestInvoker.invokeTestMethod(TestInvoker.java:173)
at org.testng.internal.MethodRunner.runInSequence(MethodRunner.java:46)
at org.testng.internal.TestInvoker$MethodInvocationAgent.invoke(TestInvoker.java:824)
at org.testng.internal.TestInvoker.invokeTestMethods(TestInvoker.java:146)
at org.testng.internal.TestMethodWorker.invokeTestMethods(TestMethodWorker.java:146)
at org.testng.internal.TestMethodWorker.run(TestMethodWorker.java:128)
at java.base/java.util.ArrayList.forEach(ArrayList.java:1511)
at org.testng.TestRunner.privateRun(TestRunner.java:794)
at org.testng.TestRunner.run(TestRunner.java:596)
at org.testng.SuiteRunner.runTest(SuiteRunner.java:377)
at org.testng.SuiteRunner.runSequentially(SuiteRunner.java:371)
at org.testng.SuiteRunner.privateRun(SuiteRunner.java:332)
at org.testng.SuiteRunner.run(SuiteRunner.java:276)
at org.testng.SuiteRunnerWorker.runSuite(SuiteRunnerWorker.java:53)
at org.testng.SuiteRunnerWorker.run(SuiteRunnerWorker.java:96)
at org.testng.TestNG.runSuitesSequentially(TestNG.java:1212)
at org.testng.TestNG.runSuitesLocally(TestNG.java:1134)
at org.testng.TestNG.runSuites(TestNG.java:1063)
at org.testng.TestNG.run(TestNG.java:1031)
at org.testng.remote.AbstractRemoteTestNG.run(AbstractRemoteTestNG.java:115)
at org.testng.remote.RemoteTestNG.initAndRun(RemoteTestNG.java:251)
at org.testng.remote.RemoteTestNG.main(RemoteTestNG.java:77)
]]>
            </full-stacktrace>
          </exception> <!-- java.lang.AssertionError -->
          <reporter-output>
          </reporter-output>
        </test-method> <!-- check_the_number_searches -->
        <test-method is-config="true" signature="theEnd()[pri:0, instance:xyzfinal.Myclass@110844f6]" started-at="2023-03-03T15:19:08 EET" name="theEnd" finished-at="2023-03-03T15:19:08 EET" duration-ms="1" status="PASS">
          <reporter-output>
          </reporter-output>
        </test-method> <!-- theEnd -->
      </class> <!-- xyzfinal.Myclass -->
    </test> <!-- Default test -->
  </suite> <!-- Default suite -->
</testng-results>
